Workbook

Sheet Dashboard
A1: FINANCIAL DASHBOARD
A3: FINANCIAL OVERVIEW | F3: MONTHLY BREAKDOWN
A4: Total Income | B4: =SUMPRODUCT((Income!D3:D502)*1) | F4: Month | G4: Income | H4: Spending | I4: Net
A5: Total Spending | B5: =SUMPRODUCT((Transactions!E3:E1002)*1) | F5: 2026-01 | G5: =SUMPRODUCT((EXACT(Income!F3:F502,F5))*(Income!D3:D502)) | H5: =SUMPRODUCT((EXACT(Transactions!G3:G1002,F5))*(Transactions!E3:E1002)) | I5: =G5-H5
A6: Net (Income-Spend) | B6: =B4-B5 | F6: 2026-02 | G6: =SUMPRODUCT((EXACT(Income!F3:F502,F6))*(Income!D3:D502)) | H6: =SUMPRODUCT((EXACT(Transactions!G3:G1002,F6))*(Transactions!E3:E1002)) | I6: =G6-H6
A7: Total Savings | B7: =SUMPRODUCT((EXACT(Savings!C3:C502,"Deposit"))*(Savings!D3:D502))-SUMPRODUCT((EXACT(Savings!C3:C502,"Withdrawal"))*(Savings!D3:D502)) | F7: 2026-03 | G7: =SUMPRODUCT((EXACT(Income!F3:F502,F7))*(Income!D3:D502)) | H7: =SUMPRODUCT((EXACT(Transactions!G3:G1002,F7))*(Transactions!E3:E1002)) | I7: =G7-H7
A8: Total Assets | B8: =SUMPRODUCT((Assets!E3:E202)*1) | F8: 2026-04 | G8: =SUMPRODUCT((EXACT(Income!F3:F502,F8))*(Income!D3:D502)) | H8: =SUMPRODUCT((EXACT(Transactions!G3:G1002,F8))*(Transactions!E3:E1002)) | I8: =G8-H8
A9: NET WORTH | B9: =B7+B8 | F9: 2026-05 | G9: =SUMPRODUCT((EXACT(Income!F3:F502,F9))*(Income!D3:D502)) | H9: =SUMPRODUCT((EXACT(Transactions!G3:G1002,F9))*(Transactions!E3:E1002)) | I9: =G9-H9
F10: 2026-06 | G10: =SUMPRODUCT((EXACT(Income!F3:F502,F10))*(Income!D3:D502)) | H10: =SUMPRODUCT((EXACT(Transactions!G3:G1002,F10))*(Transactions!E3:E1002)) | I10: =G10-H10
A11: SPENDING BY CATEGORY | F11: 2026-07 | G11: =SUMPRODUCT((EXACT(Income!F3:F502,F11))*(Income!D3:D502)) | H11: =SUMPRODUCT((EXACT(Transactions!G3:G1002,F11))*(Transactions!E3:E1002)) | I11: =G11-H11
A12: Category | B12: Total Spent | C12: % of Total | D12: Avg per Txn | F12: 2026-08 | G12: =SUMPRODUCT((EXACT(Income!F3:F502,F12))*(Income!D3:D502)) | H12: =SUMPRODUCT((EXACT(Transactions!G3:G1002,F12))*(Transactions!E3:E1002)) | I12: =G12-H12
A13: Food & Groceries | B13: =SUMPRODUCT((EXACT(Transactions!C3:C1002,A13))*(Transactions!E3:E1002)) | C13: =IF(B5<>0,B13/B5,0) | D13: =IF(COUNTIF(Transactions!C3:C1002,A13)>0,B13/COUNTIF(Transactions!C3:C1002,A13),0) | F13: 2026-09 | G13: =SUMPRODUCT((EXACT(Income!F3:F502,F13))*(Income!D3:D502)) | H13: =SUMPRODUCT((EXACT(Transactions!G3:G1002,F13))*(Transactions!E3:E1002)) | I13: =G13-H13
A14: Transportation | B14: =SUMPRODUCT((EXACT(Transactions!C3:C1002,A14))*(Transactions!E3:E1002)) | C14: =IF(B5<>0,B14/B5,0) | D14: =IF(COUNTIF(Transactions!C3:C1002,A14)>0,B14/COUNTIF(Transactions!C3:C1002,A14),0) | F14: 2026-10 | G14: =SUMPRODUCT((EXACT(Income!F3:F502,F14))*(Income!D3:D502)) | H14: =SUMPRODUCT((EXACT(Transactions!G3:G1002,F14))*(Transactions!E3:E1002)) | I14: =G14-H14
A15: Housing | B15: =SUMPRODUCT((EXACT(Transactions!C3:C1002,A15))*(Transactions!E3:E1002)) | C15: =IF(B5<>0,B15/B5,0) | D15: =IF(COUNTIF(Transactions!C3:C1002,A15)>0,B15/COUNTIF(Transactions!C3:C1002,A15),0) | F15: 2026-11 | G15: =SUMPRODUCT((EXACT(Income!F3:F502,F15))*(Income!D3:D502)) | H15: =SUMPRODUCT((EXACT(Transactions!G3:G1002,F15))*(Transactions!E3:E1002)) | I15: =G15-H15
A16: Entertainment | B16: =SUMPRODUCT((EXACT(Transactions!C3:C1002,A16))*(Transactions!E3:E1002)) | C16: =IF(B5<>0,B16/B5,0) | D16: =IF(COUNTIF(Transactions!C3:C1002,A16)>0,B16/COUNTIF(Transactions!C3:C1002,A16),0) | F16: 2026-12 | G16: =SUMPRODUCT((EXACT(Income!F3:F502,F16))*(Income!D3:D502)) | H16: =SUMPRODUCT((EXACT(Transactions!G3:G1002,F16))*(Transactions!E3:E1002)) | I16: =G16-H16
A17: Healthcare | B17: =SUMPRODUCT((EXACT(Transactions!C3:C1002,A17))*(Transactions!E3:E1002)) | C17: =IF(B5<>0,B17/B5,0) | D17: =IF(COUNTIF(Transactions!C3:C1002,A17)>0,B17/COUNTIF(Transactions!C3:C1002,A17),0) | F17: YEARLY TOTAL | G17: =SUM(G5:G16) | H17: =SUM(H5:H16) | I17: =SUM(I5:I16)
A18: Education | B18: =SUMPRODUCT((EXACT(Transactions!C3:C1002,A18))*(Transactions!E3:E1002)) | C18: =IF(B5<>0,B18/B5,0) | D18: =IF(COUNTIF(Transactions!C3:C1002,A18)>0,B18/COUNTIF(Transactions!C3:C1002,A18),0)
A19: Shopping | B19: =SUMPRODUCT((EXACT(Transactions!C3:C1002,A19))*(Transactions!E3:E1002)) | C19: =IF(B5<>0,B19/B5,0) | D19: =IF(COUNTIF(Transactions!C3:C1002,A19)>0,B19/COUNTIF(Transactions!C3:C1002,A19),0)
A20: Bills & Utilities | B20: =SUMPRODUCT((EXACT(Transactions!C3:C1002,A20))*(Transactions!E3:E1002)) | C20: =IF(B5<>0,B20/B5,0) | D20: =IF(COUNTIF(Transactions!C3:C1002,A20)>0,B20/COUNTIF(Transactions!C3:C1002,A20),0)
A21: TOTAL | B21: =SUM(B13:B20) | C21: 1
A23: SAVINGS OVERVIEW
A24: Account | B24: Total Deposits | C24: Total Withdrawals | D24: Net Savings
A25: Emergency Fund | B25: =SUMPRODUCT((EXACT(Savings!B3:B502,A25))*(EXACT(Savings!C3:C502,"Deposit"))*(Savings!D3:D502)) | C25: =SUMPRODUCT((EXACT(Savings!B3:B502,A25))*(EXACT(Savings!C3:C502,"Withdrawal"))*(Savings!D3:D502)) | D25: =B25-C25
A26: Vacation | B26: =SUMPRODUCT((EXACT(Savings!B3:B502,A26))*(EXACT(Savings!C3:C502,"Deposit"))*(Savings!D3:D502)) | C26: =SUMPRODUCT((EXACT(Savings!B3:B502,A26))*(EXACT(Savings!C3:C502,"Withdrawal"))*(Savings!D3:D502)) | D26: =B26-C26
A27: Investment | B27: =SUMPRODUCT((EXACT(Savings!B3:B502,A27))*(EXACT(Savings!C3:C502,"Deposit"))*(Savings!D3:D502)) | C27: =SUMPRODUCT((EXACT(Savings!B3:B502,A27))*(EXACT(Savings!C3:C502,"Withdrawal"))*(Savings!D3:D502)) | D27: =B27-C27
A28: Retirement | B28: =SUMPRODUCT((EXACT(Savings!B3:B502,A28))*(EXACT(Savings!C3:C502,"Deposit"))*(Savings!D3:D502)) | C28: =SUMPRODUCT((EXACT(Savings!B3:B502,A28))*(EXACT(Savings!C3:C502,"Withdrawal"))*(Savings!D3:D502)) | D28: =B28-C28
A29: Other | B29: =SUMPRODUCT((EXACT(Savings!B3:B502,A29))*(EXACT(Savings!C3:C502,"Deposit"))*(Savings!D3:D502)) | C29: =SUMPRODUCT((EXACT(Savings!B3:B502,A29))*(EXACT(Savings!C3:C502,"Withdrawal"))*(Savings!D3:D502)) | D29: =B29-C29
A30: TOTAL | B30: =SUM(B25:B29) | C30: =SUM(C25:C29) | D30: =SUM(D25:D29)

Sheet Advisor
A1: PENASIHAT KEUANGAN / FINANCIAL ADVISOR
A2: Analisis otomatis berdasarkan standar keuangan Indonesia (OJK & BI)
A4: SKOR KESEHATAN KEUANGAN | F4: ANALISIS TREN BULANAN
A5: Indikator / Indicator | B5: Nilai Anda | C5: Target (ID) | D5: Status | F5: Bulan | G5: Savings Rate | H5: Pengeluaran | I5: Nasihat / Advice
A6: Rasio Tabungan (Savings Rate) | B6: =IF(Dashboard!B4>0,(Dashboard!B4-Dashboard!B5)/Dashboard!B4,0) | C6: >= 20% (ideal ID) | D6: =IF(B6>=0.2,"SEHAT",IF(B6>=0.1,"CUKUP",IF(B6>=0.05,"MINIMUM","KURANG"))) | F6: 2026-01 | G6: =IF(SUMPRODUCT((EXACT(Income!F3:F502,F6))*(Income!D3:D502))>0,(SUMPRODUCT((EXACT(Income!F3:F502,F6))*(Income!D3:D502))-SUMPRODUCT((EXACT(Transactions!G3:G1002,F6))*(Transactions!E3:E1002)))/SUMPRODUCT((EXACT(Income!F3:F502,F6))*(Income!D3:D502)),"") | H6: =SUMPRODUCT((EXACT(Transactions!G3:G1002,F6))*(Transactions!E3:E1002)) | I6: =IF(SUMPRODUCT((EXACT(Income!F3:F502,F6))*(Income!D3:D502))=0,"Belum ada data",IF((SUMPRODUCT((EXACT(Income!F3:F502,F6))*(Income!D3:D502))-SUMPRODUCT((EXACT(Transactions!G3:G1002,F6))*(Transactions!E3:E1002)))/SUMPRODUCT((EXACT(Income!F3:F502,F6))*(Income!D3:D502))>=0.3,"Luar biasa! Nabung >30%. Pertimbangkan investasi reksadana/SBN.",IF((SUMPRODUCT((EXACT(Income!F3:F502,F6))*(Income!D3:D502))-SUMPRODUCT((EXACT(Transactions!G3:G1002,F6))*(Transactions!E3:E1002)))/SUMPRODUCT((EXACT(Income!F3:F502,F6))*(Income!D3:D502))>=0.2,"Bagus. Sesuai target 20%. Tetap konsisten!",IF((SUMPRODUCT((EXACT(Income!F3:F502,F6))*(Income!D3:D502))-SUMPRODUCT((EXACT(Transactions!G3:G1002,F6))*(Transactions!E3:E1002)))/SUMPRODUCT((EXACT(Income!F3:F502,F6))*(Income!D3:D502))>=0.1,"Cukup, tapi di bawah ideal. Kurangi jajan & belanja online.",IF((SUMPRODUCT((EXACT(Income!F3:F502,F6))*(Income!D3:D502))-SUMPRODUCT((EXACT(Transactions!G3:G1002,F6))*(Transactions!E3:E1002)))/SUMPRODUCT((EXACT(Income!F3:F502,F6))*(Income!D3:D502))>=0,"Peringatan: Nabung <10%. Cek tagihan & langganan.","BAHAYA: Pengeluaran > pemasukan! Segera kurangi pengeluaran.")))))
A7: Dana Darurat (Emergency Fund) | B7: =IF(Dashboard!B5>0,SUMPRODUCT((EXACT(Savings!B3:B502,"Emergency Fund"))*(EXACT(Savings!C3:C502,"Deposit"))*(Savings!D3:D502))/(Dashboard!B5/MAX(COUNTIF(Transactions!G3:G1002,"<>"),1)),0) | C7: >= 6 bulan (karyawan tetap) | D7: =IF(B7>=6,"SEHAT",IF(B7>=3,"CUKUP","KURANG - Prioritaskan!")) | F7: 2026-02 | G7: =IF(SUMPRODUCT((EXACT(Income!F3:F502,F7))*(Income!D3:D502))>0,(SUMPRODUCT((EXACT(Income!F3:F502,F7))*(Income!D3:D502))-SUMPRODUCT((EXACT(Transactions!G3:G1002,F7))*(Transactions!E3:E1002)))/SUMPRODUCT((EXACT(Income!F3:F502,F7))*(Income!D3:D502)),"") | H7: =SUMPRODUCT((EXACT(Transactions!G3:G1002,F7))*(Transactions!E3:E1002)) | I7: =IF(SUMPRODUCT((EXACT(Income!F3:F502,F7))*(Income!D3:D502))=0,"Belum ada data",IF((SUMPRODUCT((EXACT(Income!F3:F502,F7))*(Income!D3:D502))-SUMPRODUCT((EXACT(Transactions!G3:G1002,F7))*(Transactions!E3:E1002)))/SUMPRODUCT((EXACT(Income!F3:F502,F7))*(Income!D3:D502))>=0.3,"Luar biasa! Nabung >30%. Pertimbangkan investasi reksadana/SBN.",IF((SUMPRODUCT((EXACT(Income!F3:F502,F7))*(Income!D3:D502))-SUMPRODUCT((EXACT(Transactions!G3:G1002,F7))*(Transactions!E3:E1002)))/SUMPRODUCT((EXACT(Income!F3:F502,F7))*(Income!D3:D502))>=0.2,"Bagus. Sesuai target 20%. Tetap konsisten!",IF((SUMPRODUCT((EXACT(Income!F3:F502,F7))*(Income!D3:D502))-SUMPRODUCT((EXACT(Transactions!G3:G1002,F7))*(Transactions!E3:E1002)))/SUMPRODUCT((EXACT(Income!F3:F502,F7))*(Income!D3:D502))>=0.1,"Cukup, tapi di bawah ideal. Kurangi jajan & belanja online.",IF((SUMPRODUCT((EXACT(Income!F3:F502,F7))*(Income!D3:D502))-SUMPRODUCT((EXACT(Transactions!G3:G1002,F7))*(Transactions!E3:E1002)))/SUMPRODUCT((EXACT(Income!F3:F502,F7))*(Income!D3:D502))>=0,"Peringatan: Nabung <10%. Cek tagihan & langganan.","BAHAYA: Pengeluaran > pemasukan! Segera kurangi pengeluaran.")))))
A8: Rasio Pengeluaran (Spending) | B8: =IF(Dashboard!B4>0,Dashboard!B5/Dashboard!B4,0) | C8: <= 70% dari income | D8: =IF(B8<=0.7,"SEHAT",IF(B8<=0.85,"AWAS","BOROS - Kurangi!")) | F8: 2026-03 | G8: =IF(SUMPRODUCT((EXACT(Income!F3:F502,F8))*(Income!D3:D502))>0,(SUMPRODUCT((EXACT(Income!F3:F502,F8))*(Income!D3:D502))-SUMPRODUCT((EXACT(Transactions!G3:G1002,F8))*(Transactions!E3:E1002)))/SUMPRODUCT((EXACT(Income!F3:F502,F8))*(Income!D3:D502)),"") | H8: =SUMPRODUCT((EXACT(Transactions!G3:G1002,F8))*(Transactions!E3:E1002)) | I8: =IF(SUMPRODUCT((EXACT(Income!F3:F502,F8))*(Income!D3:D502))=0,"Belum ada data",IF((SUMPRODUCT((EXACT(Income!F3:F502,F8))*(Income!D3:D502))-SUMPRODUCT((EXACT(Transactions!G3:G1002,F8))*(Transactions!E3:E1002)))/SUMPRODUCT((EXACT(Income!F3:F502,F8))*(Income!D3:D502))>=0.3,"Luar biasa! Nabung >30%. Pertimbangkan investasi reksadana/SBN.",IF((SUMPRODUCT((EXACT(Income!F3:F502,F8))*(Income!D3:D502))-SUMPRODUCT((EXACT(Transactions!G3:G1002,F8))*(Transactions!E3:E1002)))/SUMPRODUCT((EXACT(Income!F3:F502,F8))*(Income!D3:D502))>=0.2,"Bagus. Sesuai target 20%. Tetap konsisten!",IF((SUMPRODUCT((EXACT(Income!F3:F502,F8))*(Income!D3:D502))-SUMPRODUCT((EXACT(Transactions!G3:G1002,F8))*(Transactions!E3:E1002)))/SUMPRODUCT((EXACT(Income!F3:F502,F8))*(Income!D3:D502))>=0.1,"Cukup, tapi di bawah ideal. Kurangi jajan & belanja online.",IF((SUMPRODUCT((EXACT(Income!F3:F502,F8))*(Income!D3:D502))-SUMPRODUCT((EXACT(Transactions!G3:G1002,F8))*(Transactions!E3:E1002)))/SUMPRODUCT((EXACT(Income!F3:F502,F8))*(Income!D3:D502))>=0,"Peringatan: Nabung <10%. Cek tagihan & langganan.","BAHAYA: Pengeluaran > pemasukan! Segera kurangi pengeluaran.")))))
A9: Kepatuhan Budget | B9: =IF(COUNTA(Budget!E3:E10)>0,COUNTIF(Budget!E3:E10,"OK")/COUNTA(Budget!E3:E10),0) | C9: 100% on budget | D9: =IF(B9>=0.9,"SEHAT",IF(B9>=0.7,"CUKUP","KURANG - Review budget")) | F9: 2026-04 | G9: =IF(SUMPRODUCT((EXACT(Income!F3:F502,F9))*(Income!D3:D502))>0,(SUMPRODUCT((EXACT(Income!F3:F502,F9))*(Income!D3:D502))-SUMPRODUCT((EXACT(Transactions!G3:G1002,F9))*(Transactions!E3:E1002)))/SUMPRODUCT((EXACT(Income!F3:F502,F9))*(Income!D3:D502)),"") | H9: =SUMPRODUCT((EXACT(Transactions!G3:G1002,F9))*(Transactions!E3:E1002)) | I9: =IF(SUMPRODUCT((EXACT(Income!F3:F502,F9))*(Income!D3:D502))=0,"Belum ada data",IF((SUMPRODUCT((EXACT(Income!F3:F502,F9))*(Income!D3:D502))-SUMPRODUCT((EXACT(Transactions!G3:G1002,F9))*(Transactions!E3:E1002)))/SUMPRODUCT((EXACT(Income!F3:F502,F9))*(Income!D3:D502))>=0.3,"Luar biasa! Nabung >30%. Pertimbangkan investasi reksadana/SBN.",IF((SUMPRODUCT((EXACT(Income!F3:F502,F9))*(Income!D3:D502))-SUMPRODUCT((EXACT(Transactions!G3:G1002,F9))*(Transactions!E3:E1002)))/SUMPRODUCT((EXACT(Income!F3:F502,F9))*(Income!D3:D502))>=0.2,"Bagus. Sesuai target 20%. Tetap konsisten!",IF((SUMPRODUCT((EXACT(Income!F3:F502,F9))*(Income!D3:D502))-SUMPRODUCT((EXACT(Transactions!G3:G1002,F9))*(Transactions!E3:E1002)))/SUMPRODUCT((EXACT(Income!F3:F502,F9))*(Income!D3:D502))>=0.1,"Cukup, tapi di bawah ideal. Kurangi jajan & belanja online.",IF((SUMPRODUCT((EXACT(Income!F3:F502,F9))*(Income!D3:D502))-SUMPRODUCT((EXACT(Transactions!G3:G1002,F9))*(Transactions!E3:E1002)))/SUMPRODUCT((EXACT(Income!F3:F502,F9))*(Income!D3:D502))>=0,"Peringatan: Nabung <10%. Cek tagihan & langganan.","BAHAYA: Pengeluaran > pemasukan! Segera kurangi pengeluaran.")))))
A10: Kebutuhan vs Keinginan | B10: =IF(Dashboard!B5>0,(SUMPRODUCT((EXACT(Transactions!C3:C1002,"Food & Groceries"))*(Transactions!E3:E1002))+SUMPRODUCT((EXACT(Transactions!C3:C1002,"Housing"))*(Transactions!E3:E1002))+SUMPRODUCT((EXACT(Transactions!C3:C1002,"Bills & Utilities"))*(Transactions!E3:E1002))+SUMPRODUCT((EXACT(Transactions!C3:C1002,"Healthcare"))*(Transactions!E3:E1002))+SUMPRODUCT((EXACT(Transactions!C3:C1002,"Transportation"))*(Transactions!E3:E1002)))/Dashboard!B5,0) | C10: 40-50% kebutuhan pokok | D10: =IF(AND(B10>=0.35,B10<=0.55),"SEHAT",IF(B10>0.55,"TERLALU TINGGI","RENDAH")) | F10: 2026-05 | G10: =IF(SUMPRODUCT((EXACT(Income!F3:F502,F10))*(Income!D3:D502))>0,(SUMPRODUCT((EXACT(Income!F3:F502,F10))*(Income!D3:D502))-SUMPRODUCT((EXACT(Transactions!G3:G1002,F10))*(Transactions!E3:E1002)))/SUMPRODUCT((EXACT(Income!F3:F502,F10))*(Income!D3:D502)),"") | H10: =SUMPRODUCT((EXACT(Transactions!G3:G1002,F10))*(Transactions!E3:E1002)) | I10: =IF(SUMPRODUCT((EXACT(Income!F3:F502,F10))*(Income!D3:D502))=0,"Belum ada data",IF((SUMPRODUCT((EXACT(Income!F3:F502,F10))*(Income!D3:D502))-SUMPRODUCT((EXACT(Transactions!G3:G1002,F10))*(Transactions!E3:E1002)))/SUMPRODUCT((EXACT(Income!F3:F502,F10))*(Income!D3:D502))>=0.3,"Luar biasa! Nabung >30%. Pertimbangkan investasi reksadana/SBN.",IF((SUMPRODUCT((EXACT(Income!F3:F502,F10))*(Income!D3:D502))-SUMPRODUCT((EXACT(Transactions!G3:G1002,F10))*(Transactions!E3:E1002)))/SUMPRODUCT((EXACT(Income!F3:F502,F10))*(Income!D3:D502))>=0.2,"Bagus. Sesuai target 20%. Tetap konsisten!",IF((SUMPRODUCT((EXACT(Income!F3:F502,F10))*(Income!D3:D502))-SUMPRODUCT((EXACT(Transactions!G3:G1002,F10))*(Transactions!E3:E1002)))/SUMPRODUCT((EXACT(Income!F3:F502,F10))*(Income!D3:D502))>=0.1,"Cukup, tapi di bawah ideal. Kurangi jajan & belanja online.",IF((SUMPRODUCT((EXACT(Income!F3:F502,F10))*(Income!D3:D502))-SUMPRODUCT((EXACT(Transactions!G3:G1002,F10))*(Transactions!E3:E1002)))/SUMPRODUCT((EXACT(Income!F3:F502,F10))*(Income!D3:D502))>=0,"Peringatan: Nabung <10%. Cek tagihan & langganan.","BAHAYA: Pengeluaran > pemasukan! Segera kurangi pengeluaran.")))))
A11: Alokasi Investasi (% NW) | B11: =IF(Dashboard!B9>0,Dashboard!B8/Dashboard!B9,0) | C11: >= 30% dari net worth | D11: =IF(B11>=0.3,"SEHAT",IF(B11>=0.15,"CUKUP","KURANG - Mulai investasi!")) | F11: 2026-06 | G11: =IF(SUMPRODUCT((EXACT(Income!F3:F502,F11))*(Income!D3:D502))>0,(SUMPRODUCT((EXACT(Income!F3:F502,F11))*(Income!D3:D502))-SUMPRODUCT((EXACT(Transactions!G3:G1002,F11))*(Transactions!E3:E1002)))/SUMPRODUCT((EXACT(Income!F3:F502,F11))*(Income!D3:D502)),"") | H11: =SUMPRODUCT((EXACT(Transactions!G3:G1002,F11))*(Transactions!E3:E1002)) | I11: =IF(SUMPRODUCT((EXACT(Income!F3:F502,F11))*(Income!D3:D502))=0,"Belum ada data",IF((SUMPRODUCT((EXACT(Income!F3:F502,F11))*(Income!D3:D502))-SUMPRODUCT((EXACT(Transactions!G3:G1002,F11))*(Transactions!E3:E1002)))/SUMPRODUCT((EXACT(Income!F3:F502,F11))*(Income!D3:D502))>=0.3,"Luar biasa! Nabung >30%. Pertimbangkan investasi reksadana/SBN.",IF((SUMPRODUCT((EXACT(Income!F3:F502,F11))*(Income!D3:D502))-SUMPRODUCT((EXACT(Transactions!G3:G1002,F11))*(Transactions!E3:E1002)))/SUMPRODUCT((EXACT(Income!F3:F502,F11))*(Income!D3:D502))>=0.2,"Bagus. Sesuai target 20%. Tetap konsisten!",IF((SUMPRODUCT((EXACT(Income!F3:F502,F11))*(Income!D3:D502))-SUMPRODUCT((EXACT(Transactions!G3:G1002,F11))*(Transactions!E3:E1002)))/SUMPRODUCT((EXACT(Income!F3:F502,F11))*(Income!D3:D502))>=0.1,"Cukup, tapi di bawah ideal. Kurangi jajan & belanja online.",IF((SUMPRODUCT((EXACT(Income!F3:F502,F11))*(Income!D3:D502))-SUMPRODUCT((EXACT(Transactions!G3:G1002,F11))*(Transactions!E3:E1002)))/SUMPRODUCT((EXACT(Income!F3:F502,F11))*(Income!D3:D502))>=0,"Peringatan: Nabung <10%. Cek tagihan & langganan.","BAHAYA: Pengeluaran > pemasukan! Segera kurangi pengeluaran.")))))
A12: Rasio Utang (Debt-to-Income) | B12: =0 | C12: < 30% (BI standard) | D12: =IF(B12<0.3,"SEHAT",IF(B12<0.4,"AWAS","BAHAYA - BI limit 30-40%")) | F12: 2026-07 | G12: =IF(SUMPRODUCT((EXACT(Income!F3:F502,F12))*(Income!D3:D502))>0,(SUMPRODUCT((EXACT(Income!F3:F502,F12))*(Income!D3:D502))-SUMPRODUCT((EXACT(Transactions!G3:G1002,F12))*(Transactions!E3:E1002)))/SUMPRODUCT((EXACT(Income!F3:F502,F12))*(Income!D3:D502)),"") | H12: =SUMPRODUCT((EXACT(Transactions!G3:G1002,F12))*(Transactions!E3:E1002)) | I12: =IF(SUMPRODUCT((EXACT(Income!F3:F502,F12))*(Income!D3:D502))=0,"Belum ada data",IF((SUMPRODUCT((EXACT(Income!F3:F502,F12))*(Income!D3:D502))-SUMPRODUCT((EXACT(Transactions!G3:G1002,F12))*(Transactions!E3:E1002)))/SUMPRODUCT((EXACT(Income!F3:F502,F12))*(Income!D3:D502))>=0.3,"Luar biasa! Nabung >30%. Pertimbangkan investasi reksadana/SBN.",IF((SUMPRODUCT((EXACT(Income!F3:F502,F12))*(Income!D3:D502))-SUMPRODUCT((EXACT(Transactions!G3:G1002,F12))*(Transactions!E3:E1002)))/SUMPRODUCT((EXACT(Income!F3:F502,F12))*(Income!D3:D502))>=0.2,"Bagus. Sesuai target 20%. Tetap konsisten!",IF((SUMPRODUCT((EXACT(Income!F3:F502,F12))*(Income!D3:D502))-SUMPRODUCT((EXACT(Transactions!G3:G1002,F12))*(Transactions!E3:E1002)))/SUMPRODUCT((EXACT(Income!F3:F502,F12))*(Income!D3:D502))>=0.1,"Cukup, tapi di bawah ideal. Kurangi jajan & belanja online.",IF((SUMPRODUCT((EXACT(Income!F3:F502,F12))*(Income!D3:D502))-SUMPRODUCT((EXACT(Transactions!G3:G1002,F12))*(Transactions!E3:E1002)))/SUMPRODUCT((EXACT(Income!F3:F502,F12))*(Income!D3:D502))>=0,"Peringatan: Nabung <10%. Cek tagihan & langganan.","BAHAYA: Pengeluaran > pemasukan! Segera kurangi pengeluaran.")))))
A13: Pertumbuhan Net Worth | B13: =IF(Dashboard!B9>0,Dashboard!B6/Dashboard!B9,0) | C13: > inflasi (3.5%) | D13: =IF(B13>0.035,"SEHAT",IF(B13>0,"TUMBUH","MENURUN")) | F13: 2026-08 | G13: =IF(SUMPRODUCT((EXACT(Income!F3:F502,F13))*(Income!D3:D502))>0,(SUMPRODUCT((EXACT(Income!F3:F502,F13))*(Income!D3:D502))-SUMPRODUCT((EXACT(Transactions!G3:G1002,F13))*(Transactions!E3:E1002)))/SUMPRODUCT((EXACT(Income!F3:F502,F13))*(Income!D3:D502)),"") | H13: =SUMPRODUCT((EXACT(Transactions!G3:G1002,F13))*(Transactions!E3:E1002)) | I13: =IF(SUMPRODUCT((EXACT(Income!F3:F502,F13))*(Income!D3:D502))=0,"Belum ada data",IF((SUMPRODUCT((EXACT(Income!F3:F502,F13))*(Income!D3:D502))-SUMPRODUCT((EXACT(Transactions!G3:G1002,F13))*(Transactions!E3:E1002)))/SUMPRODUCT((EXACT(Income!F3:F502,F13))*(Income!D3:D502))>=0.3,"Luar biasa! Nabung >30%. Pertimbangkan investasi reksadana/SBN.",IF((SUMPRODUCT((EXACT(Income!F3:F502,F13))*(Income!D3:D502))-SUMPRODUCT((EXACT(Transactions!G3:G1002,F13))*(Transactions!E3:E1002)))/SUMPRODUCT((EXACT(Income!F3:F502,F13))*(Income!D3:D502))>=0.2,"Bagus. Sesuai target 20%. Tetap konsisten!",IF((SUMPRODUCT((EXACT(Income!F3:F502,F13))*(Income!D3:D502))-SUMPRODUCT((EXACT(Transactions!G3:G1002,F13))*(Transactions!E3:E1002)))/SUMPRODUCT((EXACT(Income!F3:F502,F13))*(Income!D3:D502))>=0.1,"Cukup, tapi di bawah ideal. Kurangi jajan & belanja online.",IF((SUMPRODUCT((EXACT(Income!F3:F502,F13))*(Income!D3:D502))-SUMPRODUCT((EXACT(Transactions!G3:G1002,F13))*(Transactions!E3:E1002)))/SUMPRODUCT((EXACT(Income!F3:F502,F13))*(Income!D3:D502))>=0,"Peringatan: Nabung <10%. Cek tagihan & langganan.","BAHAYA: Pengeluaran > pemasukan! Segera kurangi pengeluaran.")))))
F14: 2026-09 | G14: =IF(SUMPRODUCT((EXACT(Income!F3:F502,F14))*(Income!D3:D502))>0,(SUMPRODUCT((EXACT(Income!F3:F502,F14))*(Income!D3:D502))-SUMPRODUCT((EXACT(Transactions!G3:G1002,F14))*(Transactions!E3:E1002)))/SUMPRODUCT((EXACT(Income!F3:F502,F14))*(Income!D3:D502)),"") | H14: =SUMPRODUCT((EXACT(Transactions!G3:G1002,F14))*(Transactions!E3:E1002)) | I14: =IF(SUMPRODUCT((EXACT(Income!F3:F502,F14))*(Income!D3:D502))=0,"Belum ada data",IF((SUMPRODUCT((EXACT(Income!F3:F502,F14))*(Income!D3:D502))-SUMPRODUCT((EXACT(Transactions!G3:G1002,F14))*(Transactions!E3:E1002)))/SUMPRODUCT((EXACT(Income!F3:F502,F14))*(Income!D3:D502))>=0.3,"Luar biasa! Nabung >30%. Pertimbangkan investasi reksadana/SBN.",IF((SUMPRODUCT((EXACT(Income!F3:F502,F14))*(Income!D3:D502))-SUMPRODUCT((EXACT(Transactions!G3:G1002,F14))*(Transactions!E3:E1002)))/SUMPRODUCT((EXACT(Income!F3:F502,F14))*(Income!D3:D502))>=0.2,"Bagus. Sesuai target 20%. Tetap konsisten!",IF((SUMPRODUCT((EXACT(Income!F3:F502,F14))*(Income!D3:D502))-SUMPRODUCT((EXACT(Transactions!G3:G1002,F14))*(Transactions!E3:E1002)))/SUMPRODUCT((EXACT(Income!F3:F502,F14))*(Income!D3:D502))>=0.1,"Cukup, tapi di bawah ideal. Kurangi jajan & belanja online.",IF((SUMPRODUCT((EXACT(Income!F3:F502,F14))*(Income!D3:D502))-SUMPRODUCT((EXACT(Transactions!G3:G1002,F14))*(Transactions!E3:E1002)))/SUMPRODUCT((EXACT(Income!F3:F502,F14))*(Income!D3:D502))>=0,"Peringatan: Nabung <10%. Cek tagihan & langganan.","BAHAYA: Pengeluaran > pemasukan! Segera kurangi pengeluaran.")))))
A15: SKOR KESEHATAN TOTAL | B15: =ROUND((COUNTIF(D6:D13,"SEHAT")*3+COUNTIF(D6:D13,"CUKUP")*2+COUNTIF(D6:D13,"TUMBUH")*3+COUNTIF(D6:D13,"MINIMUM")*1+COUNTIF(D6:D13,"AWAS")*1)/(COUNTA(D6:D13)*3)*100,0) | C15: =IF(B15>=80,"Sangat Baik",IF(B15>=60,"Baik",IF(B15>=40,"Cukup","Perlu Perhatian"))) | F15: 2026-10 | G15: =IF(SUMPRODUCT((EXACT(Income!F3:F502,F15))*(Income!D3:D502))>0,(SUMPRODUCT((EXACT(Income!F3:F502,F15))*(Income!D3:D502))-SUMPRODUCT((EXACT(Transactions!G3:G1002,F15))*(Transactions!E3:E1002)))/SUMPRODUCT((EXACT(Income!F3:F502,F15))*(Income!D3:D502)),"") | H15: =SUMPRODUCT((EXACT(Transactions!G3:G1002,F15))*(Transactions!E3:E1002)) | I15: =IF(SUMPRODUCT((EXACT(Income!F3:F502,F15))*(Income!D3:D502))=0,"Belum ada data",IF((SUMPRODUCT((EXACT(Income!F3:F502,F15))*(Income!D3:D502))-SUMPRODUCT((EXACT(Transactions!G3:G1002,F15))*(Transactions!E3:E1002)))/SUMPRODUCT((EXACT(Income!F3:F502,F15))*(Income!D3:D502))>=0.3,"Luar biasa! Nabung >30%. Pertimbangkan investasi reksadana/SBN.",IF((SUMPRODUCT((EXACT(Income!F3:F502,F15))*(Income!D3:D502))-SUMPRODUCT((EXACT(Transactions!G3:G1002,F15))*(Transactions!E3:E1002)))/SUMPRODUCT((EXACT(Income!F3:F502,F15))*(Income!D3:D502))>=0.2,"Bagus. Sesuai target 20%. Tetap konsisten!",IF((SUMPRODUCT((EXACT(Income!F3:F502,F15))*(Income!D3:D502))-SUMPRODUCT((EXACT(Transactions!G3:G1002,F15))*(Transactions!E3:E1002)))/SUMPRODUCT((EXACT(Income!F3:F502,F15))*(Income!D3:D502))>=0.1,"Cukup, tapi di bawah ideal. Kurangi jajan & belanja online.",IF((SUMPRODUCT((EXACT(Income!F3:F502,F15))*(Income!D3:D502))-SUMPRODUCT((EXACT(Transactions!G3:G1002,F15))*(Transactions!E3:E1002)))/SUMPRODUCT((EXACT(Income!F3:F502,F15))*(Income!D3:D502))>=0,"Peringatan: Nabung <10%. Cek tagihan & langganan.","BAHAYA: Pengeluaran > pemasukan! Segera kurangi pengeluaran.")))))
F16: 2026-11 | G16: =IF(SUMPRODUCT((EXACT(Income!F3:F502,F16))*(Income!D3:D502))>0,(SUMPRODUCT((EXACT(Income!F3:F502,F16))*(Income!D3:D502))-SUMPRODUCT((EXACT(Transactions!G3:G1002,F16))*(Transactions!E3:E1002)))/SUMPRODUCT((EXACT(Income!F3:F502,F16))*(Income!D3:D502)),"") | H16: =SUMPRODUCT((EXACT(Transactions!G3:G1002,F16))*(Transactions!E3:E1002)) | I16: =IF(SUMPRODUCT((EXACT(Income!F3:F502,F16))*(Income!D3:D502))=0,"Belum ada data",IF((SUMPRODUCT((EXACT(Income!F3:F502,F16))*(Income!D3:D502))-SUMPRODUCT((EXACT(Transactions!G3:G1002,F16))*(Transactions!E3:E1002)))/SUMPRODUCT((EXACT(Income!F3:F502,F16))*(Income!D3:D502))>=0.3,"Luar biasa! Nabung >30%. Pertimbangkan investasi reksadana/SBN.",IF((SUMPRODUCT((EXACT(Income!F3:F502,F16))*(Income!D3:D502))-SUMPRODUCT((EXACT(Transactions!G3:G1002,F16))*(Transactions!E3:E1002)))/SUMPRODUCT((EXACT(Income!F3:F502,F16))*(Income!D3:D502))>=0.2,"Bagus. Sesuai target 20%. Tetap konsisten!",IF((SUMPRODUCT((EXACT(Income!F3:F502,F16))*(Income!D3:D502))-SUMPRODUCT((EXACT(Transactions!G3:G1002,F16))*(Transactions!E3:E1002)))/SUMPRODUCT((EXACT(Income!F3:F502,F16))*(Income!D3:D502))>=0.1,"Cukup, tapi di bawah ideal. Kurangi jajan & belanja online.",IF((SUMPRODUCT((EXACT(Income!F3:F502,F16))*(Income!D3:D502))-SUMPRODUCT((EXACT(Transactions!G3:G1002,F16))*(Transactions!E3:E1002)))/SUMPRODUCT((EXACT(Income!F3:F502,F16))*(Income!D3:D502))>=0,"Peringatan: Nabung <10%. Cek tagihan & langganan.","BAHAYA: Pengeluaran > pemasukan! Segera kurangi pengeluaran.")))))
A17: ATURAN 40/30/20/10 (Adaptasi Indonesia) | F17: 2026-12 | G17: =IF(SUMPRODUCT((EXACT(Income!F3:F502,F17))*(Income!D3:D502))>0,(SUMPRODUCT((EXACT(Income!F3:F502,F17))*(Income!D3:D502))-SUMPRODUCT((EXACT(Transactions!G3:G1002,F17))*(Transactions!E3:E1002)))/SUMPRODUCT((EXACT(Income!F3:F502,F17))*(Income!D3:D502)),"") | H17: =SUMPRODUCT((EXACT(Transactions!G3:G1002,F17))*(Transactions!E3:E1002)) | I17: =IF(SUMPRODUCT((EXACT(Income!F3:F502,F17))*(Income!D3:D502))=0,"Belum ada data",IF((SUMPRODUCT((EXACT(Income!F3:F502,F17))*(Income!D3:D502))-SUMPRODUCT((EXACT(Transactions!G3:G1002,F17))*(Transactions!E3:E1002)))/SUMPRODUCT((EXACT(Income!F3:F502,F17))*(Income!D3:D502))>=0.3,"Luar biasa! Nabung >30%. Pertimbangkan investasi reksadana/SBN.",IF((SUMPRODUCT((EXACT(Income!F3:F502,F17))*(Income!D3:D502))-SUMPRODUCT((EXACT(Transactions!G3:G1002,F17))*(Transactions!E3:E1002)))/SUMPRODUCT((EXACT(Income!F3:F502,F17))*(Income!D3:D502))>=0.2,"Bagus. Sesuai target 20%. Tetap konsisten!",IF((SUMPRODUCT((EXACT(Income!F3:F502,F17))*(Income!D3:D502))-SUMPRODUCT((EXACT(Transactions!G3:G1002,F17))*(Transactions!E3:E1002)))/SUMPRODUCT((EXACT(Income!F3:F502,F17))*(Income!D3:D502))>=0.1,"Cukup, tapi di bawah ideal. Kurangi jajan & belanja online.",IF((SUMPRODUCT((EXACT(Income!F3:F502,F17))*(Income!D3:D502))-SUMPRODUCT((EXACT(Transactions!G3:G1002,F17))*(Transactions!E3:E1002)))/SUMPRODUCT((EXACT(Income!F3:F502,F17))*(Income!D3:D502))>=0,"Peringatan: Nabung <10%. Cek tagihan & langganan.","BAHAYA: Pengeluaran > pemasukan! Segera kurangi pengeluaran.")))))
A18: Kategori | B18: Ideal % | C18: Aktual % | D18: Jumlah (Rp)
A19: Kebutuhan Pokok (Living) | B19: 0.4 | C19: =IF(Dashboard!B4>0,(SUMPRODUCT((EXACT(Transactions!C3:C1002,"Food & Groceries"))*(Transactions!E3:E1002))+SUMPRODUCT((EXACT(Transactions!C3:C1002,"Housing"))*(Transactions!E3:E1002))+SUMPRODUCT((EXACT(Transactions!C3:C1002,"Transportation"))*(Transactions!E3:E1002))+SUMPRODUCT((EXACT(Transactions!C3:C1002,"Healthcare"))*(Transactions!E3:E1002))+SUMPRODUCT((EXACT(Transactions!C3:C1002,"Bills & Utilities"))*(Transactions!E3:E1002)))/Dashboard!B4,0) | D19: =SUMPRODUCT((EXACT(Transactions!C3:C1002,"Food & Groceries"))*(Transactions!E3:E1002))+SUMPRODUCT((EXACT(Transactions!C3:C1002,"Housing"))*(Transactions!E3:E1002))+SUMPRODUCT((EXACT(Transactions!C3:C1002,"Transportation"))*(Transactions!E3:E1002))+SUMPRODUCT((EXACT(Transactions!C3:C1002,"Healthcare"))*(Transactions!E3:E1002))+SUMPRODUCT((EXACT(Transactions!C3:C1002,"Bills & Utilities"))*(Transactions!E3:E1002)) | F19: PERINGATAN CERDAS / SMART ALERTS
A20: Keinginan (Lifestyle) | B20: 0.3 | C20: =IF(Dashboard!B4>0,(SUMPRODUCT((EXACT(Transactions!C3:C1002,"Entertainment"))*(Transactions!E3:E1002))+SUMPRODUCT((EXACT(Transactions!C3:C1002,"Shopping"))*(Transactions!E3:E1002))+SUMPRODUCT((EXACT(Transactions!C3:C1002,"Education"))*(Transactions!E3:E1002)))/Dashboard!B4,0) | D20: =SUMPRODUCT((EXACT(Transactions!C3:C1002,"Entertainment"))*(Transactions!E3:E1002))+SUMPRODUCT((EXACT(Transactions!C3:C1002,"Shopping"))*(Transactions!E3:E1002))+SUMPRODUCT((EXACT(Transactions!C3:C1002,"Education"))*(Transactions!E3:E1002)) | F20: Peringatan | G20: Detail | H20: Nilai | I20: Saran
A21: Tabungan & Investasi | B21: 0.2 | C21: =IF(Dashboard!B4>0,(Dashboard!B4-Dashboard!B5)/Dashboard!B4,0) | D21: =Dashboard!B4-Dashboard!B5 | F21: Kategori Tertinggi | G21: =INDEX(Dashboard!A13:A20,MATCH(MAX(Dashboard!B13:B20),Dashboard!B13:B20,0)) | H21: =TEXT(MAX(Dashboard!B13:B20),"#,##0") | I21: Pastikan sesuai prioritas kebutuhan
A22: Sedekah/Zakat/Keluarga | B22: 0.1 | C22: =0 | D22: =0 | F22: Over Budget | G22: =COUNTIF(Budget!E3:E10,"OVER BUDGET")&" kategori melebihi budget" | H22: =IF(COUNTIF(Budget!E3:E10,"OVER BUDGET")>0,"Perlu tindakan","Semua on track!") | I22: =IF(COUNTIF(Budget!E3:E10,"OVER BUDGET")>2,"Serius: banyak kategori over budget!","Cek ulang budget bulanan")
A23: Penilaian | B23: =IF(AND(C19<=0.50,C20<=0.35,C21>=0.15),"Seimbang / Balanced","Perlu Penyesuaian") | F23: Transaksi Terbesar | G23: =MAX(Transactions!E3:E1002) | H23: =IF(MAX(Transactions!E3:E1002)>Dashboard!B4*0.1,">10% income","Normal") | I23: =IF(MAX(Transactions!E3:E1002)>Dashboard!B4*0.1,"Pengeluaran besar. Pertimbangkan cicilan atau dana darurat.","Dalam batas wajar")
F24: Rasio Makan (%) | G24: =IF(Dashboard!B5>0,SUMPRODUCT((EXACT(Transactions!C3:C1002,"Food & Groceries"))*(Transactions!E3:E1002))/Dashboard!B5,0) | I24: =IF(H24>0.3,"Makan >30% pengeluaran. Coba meal prep & masak sendiri.","Porsi makan wajar")
A25: PANDUAN INVESTASI INDONESIA | F25: Progress Tabungan | G25: =IF(SUMPRODUCT((Savings!F3:F502)*1)>0,Dashboard!B7/SUMPRODUCT((Savings!F3:F502)*1),0) | I25: =IF(H25>=0.5,"Sudah >50% target! Terus nabung!",IF(H25>0,"Progress "&TEXT(H25,"0%")&" - terus konsisten!","Tetapkan target tabungan"))
A26: Instrumen | B26: Return/thn | C26: Risiko | D26: Pajak | F26: Dana Darurat Status | G26: =IF(Dashboard!B5>0,SUMPRODUCT((EXACT(Savings!B3:B502,"Emergency Fund"))*(EXACT(Savings!C3:C502,"Deposit"))*(Savings!D3:D502))/(Dashboard!B5/MAX(COUNTIF(Transactions!G3:G1002,"<>"),1)),0) | I26: =IF(H26>=6,"Dana darurat aman (>6 bulan).",IF(H26>=3,"Dana darurat cukup (3-6 bulan). Tambah terus.","PRIORITAS: Dana darurat kurang dari 3 bulan!"))
A27: Tabungan Bank | B27: 0.5-2% | C27: Sangat Rendah | D27: 20% bunga >Rp7.5jt | F27: Kesiapan Zakat | G27: =IF(Dashboard!B9>=Config!B9,"Harta di atas nisab. Siapkan zakat 2.5%.","Belum wajib zakat mal") | H27: =IF(Dashboard!B9>=Config!B9,Dashboard!B9*0.025,0) | I27: =IF(Dashboard!B9>=Config!B9,"Perkiraan zakat: Rp "&TEXT(Dashboard!B9*0.025,"#,##0")&". Bayar via BAZNAS (bisa jadi pengurang pajak).","")
A28: Deposito | B28: 3-5% | C28: Rendah | D28: 20% bunga
A29: Reksadana Pasar Uang | B29: 3-5% | C29: Rendah | D29: BEBAS PAJAK
A30: Reksadana Pendapatan Tetap | B30: 5-8% | C30: Rendah-Sedang | D30: BEBAS PAJAK | F30: TIPS KEUANGAN INDONESIA
A31: Reksadana Campuran | B31: 6-12% | C31: Sedang | D31: BEBAS PAJAK | F31: 1. | G31: Bayar diri sendiri dulu: Sisihkan tabungan & investasi DI AWAL gajian, bukan sisa.
A32: Reksadana Saham | B32: 8-15% | C32: Tinggi | D32: BEBAS PAJAK | F32: 2. | G32: Aturan 40/30/20/10: 40% kebutuhan, 30% keinginan, 20% tabungan/investasi, 10% sedekah/keluarga.
A33: SBN Ritel (ORI/SBR/SR/ST) | B33: 5-7% | C33: Rendah (pemerintah) | D33: 10% kupon | F33: 3. | G33: Dana darurat 6 bulan: Simpan di reksadana pasar uang (return 3-5%, bebas pajak, mudah dicairkan).
A34: Saham (IDX) | B34: 10-15% | C34: Tinggi | D34: 0.1% jual | F34: 4. | G34: Investasi mulai Rp 10rb: Gunakan reksadana (Bibit, Bareksa, IPOT) - bebas pajak untuk individu.
A35: Emas (Antam/digital) | B35: 5-10% | C35: Sedang | D35: PPh capital gain | F35: 5. | G35: SBN Ritel (ORI/SBR): Obligasi pemerintah, dijamin negara, return 5-7%, pajak hanya 10%.
A36: P2P Lending (OJK) | B36: 10-18% | C36: Tinggi-Sangat Tinggi | D36: 15% bunga | F36: 6. | G36: Hindari pinjol ilegal: Cek daftar OJK. Bunga pinjol legal max 0.4%/hari sudah sangat mahal.
F37: 7. | G37: Zakat sebagai pengurang pajak: Bayar via BAZNAS, lampirkan bukti di SPT (mengurangi PKP).
A38: RINGKASAN STATUS KEUANGAN | F38: 8. | G38: BPJS JHT = tabungan jangka panjang: Jangan dicairkan dini. Tambah dengan DPLK (pengurang pajak 5%).
F39: 9. | G39: Aturan 24 jam: Untuk pembelian > Rp 200rb yang bukan kebutuhan, tunggu 24 jam sebelum beli.
A40: Pendapatan Bulanan (avg) | B40: =IF(COUNTIF(Income!F3:F502,"<>")>0,SUMPRODUCT((Income!D3:D502)*1)/MAX(COUNTIF(Income!F3:F502,"<>"),1),0) | F40: 10. | G40: THR & bonus: Gunakan rumus 50% tabungan/investasi, 30% kebutuhan, 20% keinginan.
A41: Pengeluaran Bulanan (avg) | B41: =IF(COUNTIF(Transactions!G3:G1002,"<>")>0,SUMPRODUCT((Transactions!E3:E1002)*1)/MAX(COUNTIF(Transactions!G3:G1002,"<>"),1),0) | F41: 11. | G41: Catat uang kiriman keluarga: Budget kirim orang tua sebagai pengeluaran tetap (10-20% gaji).
...

Sheet Transactions
A1: SPENDING TRACKER
A2: Date | B2: Description | C2: Category | D2: Payment Method | E2: Amount | F2: Notes | G2: Month
A3: 46027 | B3: Weekly groceries | C3: Food & Groceries | D3: Debit Card | E3: 85000 | F3: Supermarket | G3: =IF(A3<>"",TEXT(A3,"YYYY-MM"),"")
A4: 46028 | B4: Bus pass monthly | C4: Transportation | D4: E-Wallet | E4: 50000 | F4: Monthly pass | G4: =IF(A4<>"",TEXT(A4,"YYYY-MM"),"")
A5: 46029 | B5: Netflix subscription | C5: Entertainment | D5: Credit Card | E5: 54000 | F5: Monthly | G5: =IF(A5<>"",TEXT(A5,"YYYY-MM"),"")
G6: =IF(A6<>"",TEXT(A6,"YYYY-MM"),"")
G7: =IF(A7<>"",TEXT(A7,"YYYY-MM"),"")
G8: =IF(A8<>"",TEXT(A8,"YYYY-MM"),"")
G9: =IF(A9<>"",TEXT(A9,"YYYY-MM"),"")
G10: =IF(A10<>"",TEXT(A10,"YYYY-MM"),"")
G11: =IF(A11<>"",TEXT(A11,"YYYY-MM"),"")
G12: =IF(A12<>"",TEXT(A12,"YYYY-MM"),"")
G13: =IF(A13<>"",TEXT(A13,"YYYY-MM"),"")
G14: =IF(A14<>"",TEXT(A14,"YYYY-MM"),"")
G15: =IF(A15<>"",TEXT(A15,"YYYY-MM"),"")
G16: =IF(A16<>"",TEXT(A16,"YYYY-MM"),"")
G17: =IF(A17<>"",TEXT(A17,"YYYY-MM"),"")
... G1002: =IF(A1002<>"",TEXT(A1002,"YYYY-MM"),"")

Sheet Income
A1: INCOME TRACKER
A2: Date | B2: Source | C2: Category | D2: Amount | E2: Notes | F2: Month
A3: 46023 | B3: Monthly Salary | C3: Salary | D3: 5000000 | E3: January salary | F3: =IF(A3<>"",TEXT(A3,"YYYY-MM"),"")
F4: =IF(A4<>"",TEXT(A4,"YYYY-MM"),"")
F5: =IF(A5<>"",TEXT(A5,"YYYY-MM"),"")
F6: =IF(A6<>"",TEXT(A6,"YYYY-MM"),"")
F7: =IF(A7<>"",TEXT(A7,"YYYY-MM"),"")
F8: =IF(A8<>"",TEXT(A8,"YYYY-MM"),"")
F9: =IF(A9<>"",TEXT(A9,"YYYY-MM"),"")
F10: =IF(A10<>"",TEXT(A10,"YYYY-MM"),"")
F11: =IF(A11<>"",TEXT(A11,"YYYY-MM"),"")
F12: =IF(A12<>"",TEXT(A12,"YYYY-MM"),"")
F13: =IF(A13<>"",TEXT(A13,"YYYY-MM"),"")
F14: =IF(A14<>"",TEXT(A14,"YYYY-MM"),"")
F15: =IF(A15<>"",TEXT(A15,"YYYY-MM"),"")
... F502: =IF(A502<>"",TEXT(A502,"YYYY-MM"),"")

Sheet Savings
A1: SAVINGS TRACKER
A2: Date | B2: Account | C2: Type | D2: Amount | E2: Balance After | F2: Goal | G2: Progress
A3: 46023 | B3: Emergency Fund | C3: Deposit | D3: 1000000 | E3: 1000000 | F3: 10000000 | G3: =IF(AND(E3<>"",F3<>"",F3<>0),E3/F3,"")
A4: 46023 | B4: Vacation | C4: Deposit | D4: 500000 | E4: 500000 | F4: 3000000 | G4: =IF(AND(E4<>"",F4<>"",F4<>0),E4/F4,"")
A5: 46023 | B5: Investment | C5: Deposit | D5: 2000000 | E5: 2000000 | F5: 20000000 | G5: =IF(AND(E5<>"",F5<>"",F5<>0),E5/F5,"")
A6: 46037 | B6: Emergency Fund | C6: Deposit | D6: 500000 | E6: 1500000 | F6: 10000000 | G6: =IF(AND(E6<>"",F6<>"",F6<>0),E6/F6,"")
G7: =IF(AND(E7<>"",F7<>"",F7<>0),E7/F7,"")
G8: =IF(AND(E8<>"",F8<>"",F8<>0),E8/F8,"")
G9: =IF(AND(E9<>"",F9<>"",F9<>0),E9/F9,"")
G10: =IF(AND(E10<>"",F10<>"",F10<>0),E10/F10,"")
G11: =IF(AND(E11<>"",F11<>"",F11<>0),E11/F11,"")
G12: =IF(AND(E12<>"",F12<>"",F12<>0),E12/F12,"")
G13: =IF(AND(E13<>"",F13<>"",F13<>0),E13/F13,"")
G14: =IF(AND(E14<>"",F14<>"",F14<>0),E14/F14,"")
G15: =IF(AND(E15<>"",F15<>"",F15<>0),E15/F15,"")
G16: =IF(AND(E16<>"",F16<>"",F16<>0),E16/F16,"")
G17: =IF(AND(E17<>"",F17<>"",F17<>0),E17/F17,"")
G18: =IF(AND(E18<>"",F18<>"",F18<>0),E18/F18,"")
... G502: =IF(AND(E502<>"",F502<>"",F502<>0),E502/F502,"")

Sheet Assets
A1: ASSETS & INVESTMENTS
A2: Date Added | B2: Name | C2: Type | D2: Purchase Value | E2: Current Value | F2: Gain/Loss | G2: Notes
F3: =IF(AND(D3<>"",E3<>""),E3-D3,"")
F4: =IF(AND(D4<>"",E4<>""),E4-D4,"")
F5: =IF(AND(D5<>"",E5<>""),E5-D5,"")
F6: =IF(AND(D6<>"",E6<>""),E6-D6,"")
F7: =IF(AND(D7<>"",E7<>""),E7-D7,"")
F8: =IF(AND(D8<>"",E8<>""),E8-D8,"")
F9: =IF(AND(D9<>"",E9<>""),E9-D9,"")
F10: =IF(AND(D10<>"",E10<>""),E10-D10,"")
F11: =IF(AND(D11<>"",E11<>""),E11-D11,"")
F12: =IF(AND(D12<>"",E12<>""),E12-D12,"")
F13: =IF(AND(D13<>"",E13<>""),E13-D13,"")
F14: =IF(AND(D14<>"",E14<>""),E14-D14,"")
... F202: =IF(AND(D202<>"",E202<>""),E202-D202,"")

Sheet Budget
A1: MONTHLY BUDGET PLANNER
A2: Category | B2: Budget Limit | C2: Actual Spent | D2: Remaining | E2: Status | G2: Budget Month: | H2: 2026-01
A3: Food & Groceries | B3: 500000 | C3: =SUMPRODUCT((EXACT(Transactions!C3:C1002,A3))*(EXACT(Transactions!G3:G1002,$H$2))*(Transactions!E3:E1002)) | D3: =IF(B3<>"",B3-C3,"") | E3: =IF(B3<>"",IF(C3>B3,"OVER BUDGET",IF(C3>B3*0.8,"WARNING","OK")),"")
A4: Transportation | B4: 200000 | C4: =SUMPRODUCT((EXACT(Transactions!C3:C1002,A4))*(EXACT(Transactions!G3:G1002,$H$2))*(Transactions!E3:E1002)) | D4: =IF(B4<>"",B4-C4,"") | E4: =IF(B4<>"",IF(C4>B4,"OVER BUDGET",IF(C4>B4*0.8,"WARNING","OK")),"")
A5: Housing | B5: 1500000 | C5: =SUMPRODUCT((EXACT(Transactions!C3:C1002,A5))*(EXACT(Transactions!G3:G1002,$H$2))*(Transactions!E3:E1002)) | D5: =IF(B5<>"",B5-C5,"") | E5: =IF(B5<>"",IF(C5>B5,"OVER BUDGET",IF(C5>B5*0.8,"WARNING","OK")),"")
A6: Entertainment | B6: 200000 | C6: =SUMPRODUCT((EXACT(Transactions!C3:C1002,A6))*(EXACT(Transactions!G3:G1002,$H$2))*(Transactions!E3:E1002)) | D6: =IF(B6<>"",B6-C6,"") | E6: =IF(B6<>"",IF(C6>B6,"OVER BUDGET",IF(C6>B6*0.8,"WARNING","OK")),"")
A7: Healthcare | B7: 300000 | C7: =SUMPRODUCT((EXACT(Transactions!C3:C1002,A7))*(EXACT(Transactions!G3:G1002,$H$2))*(Transactions!E3:E1002)) | D7: =IF(B7<>"",B7-C7,"") | E7: =IF(B7<>"",IF(C7>B7,"OVER BUDGET",IF(C7>B7*0.8,"WARNING","OK")),"")
A8: Education | B8: 200000 | C8: =SUMPRODUCT((EXACT(Transactions!C3:C1002,A8))*(EXACT(Transactions!G3:G1002,$H$2))*(Transactions!E3:E1002)) | D8: =IF(B8<>"",B8-C8,"") | E8: =IF(B8<>"",IF(C8>B8,"OVER BUDGET",IF(C8>B8*0.8,"WARNING","OK")),"")
A9: Shopping | B9: 300000 | C9: =SUMPRODUCT((EXACT(Transactions!C3:C1002,A9))*(EXACT(Transactions!G3:G1002,$H$2))*(Transactions!E3:E1002)) | D9: =IF(B9<>"",B9-C9,"") | E9: =IF(B9<>"",IF(C9>B9,"OVER BUDGET",IF(C9>B9*0.8,"WARNING","OK")),"")
A10: Bills & Utilities | B10: 500000 | C10: =SUMPRODUCT((EXACT(Transactions!C3:C1002,A10))*(EXACT(Transactions!G3:G1002,$H$2))*(Transactions!E3:E1002)) | D10: =IF(B10<>"",B10-C10,"") | E10: =IF(B10<>"",IF(C10>B10,"OVER BUDGET",IF(C10>B10*0.8,"WARNING","OK")),"")
A11: TOTAL | B11: =SUM(B3:B10) | C11: =SUM(C3:C10) | D11: =B11-C11

Sheet Config
A1: KONFIGURASI KEUANGAN INDONESIA
A2: Parameter | B2: Nilai | C2: Keterangan
A3: PTKP TK/0 (single) | B3: 54000000 | C3: Penghasilan Tidak Kena Pajak - Lajang
A4: PTKP K/0 (married) | B4: 58500000 | C4: Penghasilan Tidak Kena Pajak - Menikah
A5: PTKP K/1 | B5: 63000000 | C5: Menikah + 1 tanggungan
A6: PTKP K/2 | B6: 67500000 | C6: Menikah + 2 tanggungan
A7: PTKP K/3 | B7: 72000000 | C7: Menikah + 3 tanggungan
A8: Nisab Zakat Mal (Rp) | B8: 85000000 | C8: ~85 gram emas x harga emas terkini. Update manual.
A9: Tarif Zakat | B9: 0.025 | C9: 2.5% dari harta di atas nisab
A10: Inflasi Target (BI) | B10: 0.035 | C10: Target Bank Indonesia 2.5% +/- 1%
A11: BI Rate | B11: 0.0575 | C11: Suku bunga acuan Bank Indonesia
A12: Pajak Deposito | B12: 0.2 | C12: PPh final atas bunga deposito
A13: Pajak SBN Ritel | B13: 0.1 | C13: PPh final atas kupon SBN
A14: Pajak Reksadana | B14: 0 | C14: Bebas pajak untuk individu
... A20: UMP Jakarta 2026 | B20: 5500000 | C20: Upah Minimum Provinsi DKI Jakarta (est)
A22: Catatan: Nilai di atas bisa di-update sesuai kondisi terkini. Nisab zakat perlu disesuaikan dengan harga emas terbaru. PTKP dan PPh mengikuti UU HPP.
